Workbook

Sheet EVIDENCE_ENTRY
A1: OPENINTEL EVIDENCE ENTRY TEMPLATE | H1: Tag each claim · Score auto-calculates | O1: Schema.org Convergence Fields
A2: CLAIM_ID | B2: CLAIM_TEXT | C2: CASE_REF | D2: SOURCE | E2: DB_TAG | F2: TIER | G2: URL | H2: DATE_ACCESSED | I2: VERIFICATION | J2: CORROBORATION | K2: NOTES | L2: AUTHOR_NAME | M2: AUTHOR_ORG | N2: ITEM_REVIEWED | O2: REVIEW_RATING | P2: DATE_PUBLISHED | Q2: DATE_REVIEWED | R2: POSITIVE_NOTES | S2: NEGATIVE_NOTES | U2: COMPLETE | V2: QUALITY | W2: CONSIST | X2: COMPOSITE | Y2: PROMO GATE
A3: CLAIM-001 | U3: =IF(COUNTA(A3:S3)=0,"",ROUND((COUNTA(B3:S3)/18)*100,0)) -> 0 | V3: =IF(F3="","",IF(F3="T1",100,IF(F3="T2",80,IF(F3="T3",60,IF(F3="T4",35,IF(F3="T5",15,IF(F3="N",50,0))))))) | W3: =IF(OR(A3="",E3=""),"",_xlfn.LET(_xlpm.tag_valid,COUNTIF(EVIDENCE_TAXONOMY!F4:F46,E3)>0,_xlpm.tier_filled,F3<>"",_xlpm.status_valid,OR(I3="verified",I3="pending",I3="disputed",I3="unverifiable",I3=""),_xlpm.corr_ok,IF(OR(F3="T4",F3="T5"),J3>0,TRUE),_xlpm.checks,_xlpm.tag_valid+_xlpm.tier_filled+_xlpm.status_valid+_xlpm.corr_ok,ROUND((_xlpm.checks/4)*100,0))) | X3: =IF(AND(U3<>"",V3<>"",W3<>""),ROUND((U3*0.3+V3*0.4+W3*0.3),0),IF(U3<>"",U3,"")) -> 0 | Y3: =IF(B3="","",_xlfn.LET(_xlpm.core_filled,AND(B3<>"",E3<>"",F3<>"",G3<>"",I3<>""),_xlpm.author_ok,OR(L3<>"",M3<>""),_xlpm.rating_ok,O3<>"",_xlpm.corr_ok,IF(OR(F3="T4",F3="T5"),J3>=2,TRUE),_xlpm.quality_ok,V3>=60,_xlpm.composite_ok,X3>=65,_xlpm.gates_pass,AND(_xlpm.core_filled,_xlpm.author_ok,_xlpm.rating_ok,_xlpm.corr_ok,_xlpm.quality_ok,_xlpm.composite_ok),IF(_xlpm.gates_pass,"✅ READY","❌ BLOCKED")))
A4: CLAIM-002 | U4: =IF(COUNTA(A4:S4)=0,"",ROUND((COUNTA(B4:S4)/18)*100,0)) -> 0 | V4: =IF(F4="","",IF(F4="T1",100,IF(F4="T2",80,IF(F4="T3",60,IF(F4="T4",35,IF(F4="T5",15,IF(F4="N",50,0))))))) | W4: =IF(OR(A4="",E4=""),"",_xlfn.LET(_xlpm.tag_valid,COUNTIF(EVIDENCE_TAXONOMY!F4:F46,E4)>0,_xlpm.tier_filled,F4<>"",_xlpm.status_valid,OR(I4="verified",I4="pending",I4="disputed",I4="unverifiable",I4=""),_xlpm.corr_ok,IF(OR(F4="T4",F4="T5"),J4>0,TRUE),_xlpm.checks,_xlpm.tag_valid+_xlpm.tier_filled+_xlpm.status_valid+_xlpm.corr_ok,ROUND((_xlpm.checks/4)*100,0))) | X4: =IF(AND(U4<>"",V4<>"",W4<>""),ROUND((U4*0.3+V4*0.4+W4*0.3),0),IF(U4<>"",U4,"")) -> 0 | Y4: =IF(B4="","",_xlfn.LET(_xlpm.core_filled,AND(B4<>"",E4<>"",F4<>"",G4<>"",I4<>""),_xlpm.author_ok,OR(L4<>"",M4<>""),_xlpm.rating_ok,O4<>"",_xlpm.corr_ok,IF(OR(F4="T4",F4="T5"),J4>=2,TRUE),_xlpm.quality_ok,V4>=60,_xlpm.composite_ok,X4>=65,_xlpm.gates_pass,AND(_xlpm.core_filled,_xlpm.author_ok,_xlpm.rating_ok,_xlpm.corr_ok,_xlpm.quality_ok,_xlpm.composite_ok),IF(_xlpm.gates_pass,"✅ READY","❌ BLOCKED")))
A5: CLAIM-003 | U5: =IF(COUNTA(A5:S5)=0,"",ROUND((COUNTA(B5:S5)/18)*100,0)) -> 0 | V5: =IF(F5="","",IF(F5="T1",100,IF(F5="T2",80,IF(F5="T3",60,IF(F5="T4",35,IF(F5="T5",15,IF(F5="N",50,0))))))) | W5: =IF(OR(A5="",E5=""),"",_xlfn.LET(_xlpm.tag_valid,COUNTIF(EVIDENCE_TAXONOMY!F5:F47,E5)>0,_xlpm.tier_filled,F5<>"",_xlpm.status_valid,OR(I5="verified",I5="pending",I5="disputed",I5="unverifiable",I5=""),_xlpm.corr_ok,IF(OR(F5="T4",F5="T5"),J5>0,TRUE),_xlpm.checks,_xlpm.tag_valid+_xlpm.tier_filled+_xlpm.status_valid+_xlpm.corr_ok,ROUND((_xlpm.checks/4)*100,0))) | X5: =IF(AND(U5<>"",V5<>"",W5<>""),ROUND((U5*0.3+V5*0.4+W5*0.3),0),IF(U5<>"",U5,"")) -> 0 | Y5: =IF(B5="","",_xlfn.LET(_xlpm.core_filled,AND(B5<>"",E5<>"",F5<>"",G5<>"",I5<>""),_xlpm.author_ok,OR(L5<>"",M5<>""),_xlpm.rating_ok,O5<>"",_xlpm.corr_ok,IF(OR(F5="T4",F5="T5"),J5>=2,TRUE),_xlpm.quality_ok,V5>=60,_xlpm.composite_ok,X5>=65,_xlpm.gates_pass,AND(_xlpm.core_filled,_xlpm.author_ok,_xlpm.rating_ok,_xlpm.corr_ok,_xlpm.quality_ok,_xlpm.composite_ok),IF(_xlpm.gates_pass,"✅ READY","❌ BLOCKED")))
A6: CLAIM-004 | U6: =IF(COUNTA(A6:S6)=0,"",ROUND((COUNTA(B6:S6)/18)*100,0)) -> 0 | V6: =IF(F6="","",IF(F6="T1",100,IF(F6="T2",80,IF(F6="T3",60,IF(F6="T4",35,IF(F6="T5",15,IF(F6="N",50,0))))))) | W6: =IF(OR(A6="",E6=""),"",_xlfn.LET(_xlpm.tag_valid,COUNTIF(EVIDENCE_TAXONOMY!F6:F48,E6)>0,_xlpm.tier_filled,F6<>"",_xlpm.status_valid,OR(I6="verified",I6="pending",I6="disputed",I6="unverifiable",I6=""),_xlpm.corr_ok,IF(OR(F6="T4",F6="T5"),J6>0,TRUE),_xlpm.checks,_xlpm.tag_valid+_xlpm.tier_filled+_xlpm.status_valid+_xlpm.corr_ok,ROUND((_xlpm.checks/4)*100,0))) | X6: =IF(AND(U6<>"",V6<>"",W6<>""),ROUND((U6*0.3+V6*0.4+W6*0.3),0),IF(U6<>"",U6,"")) -> 0 | Y6: =IF(B6="","",_xlfn.LET(_xlpm.core_filled,AND(B6<>"",E6<>"",F6<>"",G6<>"",I6<>""),_xlpm.author_ok,OR(L6<>"",M6<>""),_xlpm.rating_ok,O6<>"",_xlpm.corr_ok,IF(OR(F6="T4",F6="T5"),J6>=2,TRUE),_xlpm.quality_ok,V6>=60,_xlpm.composite_ok,X6>=65,_xlpm.gates_pass,AND(_xlpm.core_filled,_xlpm.author_ok,_xlpm.rating_ok,_xlpm.corr_ok,_xlpm.quality_ok,_xlpm.composite_ok),IF(_xlpm.gates_pass,"✅ READY","❌ BLOCKED")))
A7: CLAIM-005 | U7: =IF(COUNTA(A7:S7)=0,"",ROUND((COUNTA(B7:S7)/18)*100,0)) -> 0 | V7: =IF(F7="","",IF(F7="T1",100,IF(F7="T2",80,IF(F7="T3",60,IF(F7="T4",35,IF(F7="T5",15,IF(F7="N",50,0))))))) | W7: =IF(OR(A7="",E7=""),"",_xlfn.LET(_xlpm.tag_valid,COUNTIF(EVIDENCE_TAXONOMY!F7:F49,E7)>0,_xlpm.tier_filled,F7<>"",_xlpm.status_valid,OR(I7="verified",I7="pending",I7="disputed",I7="unverifiable",I7=""),_xlpm.corr_ok,IF(OR(F7="T4",F7="T5"),J7>0,TRUE),_xlpm.checks,_xlpm.tag_valid+_xlpm.tier_filled+_xlpm.status_valid+_xlpm.corr_ok,ROUND((_xlpm.checks/4)*100,0))) | X7: =IF(AND(U7<>"",V7<>"",W7<>""),ROUND((U7*0.3+V7*0.4+W7*0.3),0),IF(U7<>"",U7,"")) -> 0 | Y7: =IF(B7="","",_xlfn.LET(_xlpm.core_filled,AND(B7<>"",E7<>"",F7<>"",G7<>"",I7<>""),_xlpm.author_ok,OR(L7<>"",M7<>""),_xlpm.rating_ok,O7<>"",_xlpm.corr_ok,IF(OR(F7="T4",F7="T5"),J7>=2,TRUE),_xlpm.quality_ok,V7>=60,_xlpm.composite_ok,X7>=65,_xlpm.gates_pass,AND(_xlpm.core_filled,_xlpm.author_ok,_xlpm.rating_ok,_xlpm.corr_ok,_xlpm.quality_ok,_xlpm.composite_ok),IF(_xlpm.gates_pass,"✅ READY","❌ BLOCKED")))
A8: CLAIM-006 | U8: =IF(COUNTA(A8:S8)=0,"",ROUND((COUNTA(B8:S8)/18)*100,0)) -> 0 | V8: =IF(F8="","",IF(F8="T1",100,IF(F8="T2",80,IF(F8="T3",60,IF(F8="T4",35,IF(F8="T5",15,IF(F8="N",50,0))))))) | W8: =IF(OR(A8="",E8=""),"",_xlfn.LET(_xlpm.tag_valid,COUNTIF(EVIDENCE_TAXONOMY!F8:F50,E8)>0,_xlpm.tier_filled,F8<>"",_xlpm.status_valid,OR(I8="verified",I8="pending",I8="disputed",I8="unverifiable",I8=""),_xlpm.corr_ok,IF(OR(F8="T4",F8="T5"),J8>0,TRUE),_xlpm.checks,_xlpm.tag_valid+_xlpm.tier_filled+_xlpm.status_valid+_xlpm.corr_ok,ROUND((_xlpm.checks/4)*100,0))) | X8: =IF(AND(U8<>"",V8<>"",W8<>""),ROUND((U8*0.3+V8*0.4+W8*0.3),0),IF(U8<>"",U8,"")) -> 0 | Y8: =IF(B8="","",_xlfn.LET(_xlpm.core_filled,AND(B8<>"",E8<>"",F8<>"",G8<>"",I8<>""),_xlpm.author_ok,OR(L8<>"",M8<>""),_xlpm.rating_ok,O8<>"",_xlpm.corr_ok,IF(OR(F8="T4",F8="T5"),J8>=2,TRUE),_xlpm.quality_ok,V8>=60,_xlpm.composite_ok,X8>=65,_xlpm.gates_pass,AND(_xlpm.core_filled,_xlpm.author_ok,_xlpm.rating_ok,_xlpm.corr_ok,_xlpm.quality_ok,_xlpm.composite_ok),IF(_xlpm.gates_pass,"✅ READY","❌ BLOCKED")))
A9: CLAIM-007 | U9: =IF(COUNTA(A9:S9)=0,"",ROUND((COUNTA(B9:S9)/18)*100,0)) -> 0 | V9: =IF(F9="","",IF(F9="T1",100,IF(F9="T2",80,IF(F9="T3",60,IF(F9="T4",35,IF(F9="T5",15,IF(F9="N",50,0))))))) | W9: =IF(OR(A9="",E9=""),"",_xlfn.LET(_xlpm.tag_valid,COUNTIF(EVIDENCE_TAXONOMY!F9:F51,E9)>0,_xlpm.tier_filled,F9<>"",_xlpm.status_valid,OR(I9="verified",I9="pending",I9="disputed",I9="unverifiable",I9=""),_xlpm.corr_ok,IF(OR(F9="T4",F9="T5"),J9>0,TRUE),_xlpm.checks,_xlpm.tag_valid+_xlpm.tier_filled+_xlpm.status_valid+_xlpm.corr_ok,ROUND((_xlpm.checks/4)*100,0))) | X9: =IF(AND(U9<>"",V9<>"",W9<>""),ROUND((U9*0.3+V9*0.4+W9*0.3),0),IF(U9<>"",U9,"")) -> 0 | Y9: =IF(B9="","",_xlfn.LET(_xlpm.core_filled,AND(B9<>"",E9<>"",F9<>"",G9<>"",I9<>""),_xlpm.author_ok,OR(L9<>"",M9<>""),_xlpm.rating_ok,O9<>"",_xlpm.corr_ok,IF(OR(F9="T4",F9="T5"),J9>=2,TRUE),_xlpm.quality_ok,V9>=60,_xlpm.composite_ok,X9>=65,_xlpm.gates_pass,AND(_xlpm.core_filled,_xlpm.author_ok,_xlpm.rating_ok,_xlpm.corr_ok,_xlpm.quality_ok,_xlpm.composite_ok),IF(_xlpm.gates_pass,"✅ READY","❌ BLOCKED")))
A10: CLAIM-008 | U10: =IF(COUNTA(A10:S10)=0,"",ROUND((COUNTA(B10:S10)/18)*100,0)) -> 0 | V10: =IF(F10="","",IF(F10="T1",100,IF(F10="T2",80,IF(F10="T3",60,IF(F10="T4",35,IF(F10="T5",15,IF(F10="N",50,0))))))) | W10: =IF(OR(A10="",E10=""),"",_xlfn.LET(_xlpm.tag_valid,COUNTIF(EVIDENCE_TAXONOMY!F10:F52,E10)>0,_xlpm.tier_filled,F10<>"",_xlpm.status_valid,OR(I10="verified",I10="pending",I10="disputed",I10="unverifiable",I10=""),_xlpm.corr_ok,IF(OR(F10="T4",F10="T5"),J10>0,TRUE),_xlpm.checks,_xlpm.tag_valid+_xlpm.tier_filled+_xlpm.status_valid+_xlpm.corr_ok,ROUND((_xlpm.checks/4)*100,0))) | X10: =IF(AND(U10<>"",V10<>"",W10<>""),ROUND((U10*0.3+V10*0.4+W10*0.3),0),IF(U10<>"",U10,"")) -> 0 | Y10: =IF(B10="","",_xlfn.LET(_xlpm.core_filled,AND(B10<>"",E10<>"",F10<>"",G10<>"",I10<>""),_xlpm.author_ok,OR(L10<>"",M10<>""),_xlpm.rating_ok,O10<>"",_xlpm.corr_ok,IF(OR(F10="T4",F10="T5"),J10>=2,TRUE),_xlpm.quality_ok,V10>=60,_xlpm.composite_ok,X10>=65,_xlpm.gates_pass,AND(_xlpm.core_filled,_xlpm.author_ok,_xlpm.rating_ok,_xlpm.corr_ok,_xlpm.quality_ok,_xlpm.composite_ok),IF(_xlpm.gates_pass,"✅ READY","❌ BLOCKED")))
A11: CLAIM-009 | U11: =IF(COUNTA(A11:S11)=0,"",ROUND((COUNTA(B11:S11)/18)*100,0)) -> 0 | V11: =IF(F11="","",IF(F11="T1",100,IF(F11="T2",80,IF(F11="T3",60,IF(F11="T4",35,IF(F11="T5",15,IF(F11="N",50,0))))))) | W11: =IF(OR(A11="",E11=""),"",_xlfn.LET(_xlpm.tag_valid,COUNTIF(EVIDENCE_TAXONOMY!F11:F53,E11)>0,_xlpm.tier_filled,F11<>"",_xlpm.status_valid,OR(I11="verified",I11="pending",I11="disputed",I11="unverifiable",I11=""),_xlpm.corr_ok,IF(OR(F11="T4",F11="T5"),J11>0,TRUE),_xlpm.checks,_xlpm.tag_valid+_xlpm.tier_filled+_xlpm.status_valid+_xlpm.corr_ok,ROUND((_xlpm.checks/4)*100,0))) | X11: =IF(AND(U11<>"",V11<>"",W11<>""),ROUND((U11*0.3+V11*0.4+W11*0.3),0),IF(U11<>"",U11,"")) -> 0 | Y11: =IF(B11="","",_xlfn.LET(_xlpm.core_filled,AND(B11<>"",E11<>"",F11<>"",G11<>"",I11<>""),_xlpm.author_ok,OR(L11<>"",M11<>""),_xlpm.rating_ok,O11<>"",_xlpm.corr_ok,IF(OR(F11="T4",F11="T5"),J11>=2,TRUE),_xlpm.quality_ok,V11>=60,_xlpm.composite_ok,X11>=65,_xlpm.gates_pass,AND(_xlpm.core_filled,_xlpm.author_ok,_xlpm.rating_ok,_xlpm.corr_ok,_xlpm.quality_ok,_xlpm.composite_ok),IF(_xlpm.gates_pass,"✅ READY","❌ BLOCKED")))
A12: CLAIM-010 | U12: =IF(COUNTA(A12:S12)=0,"",ROUND((COUNTA(B12:S12)/18)*100,0)) -> 0 | V12: =IF(F12="","",IF(F12="T1",100,IF(F12="T2",80,IF(F12="T3",60,IF(F12="T4",35,IF(F12="T5",15,IF(F12="N",50,0))))))) | W12: =IF(OR(A12="",E12=""),"",_xlfn.LET(_xlpm.tag_valid,COUNTIF(EVIDENCE_TAXONOMY!F12:F54,E12)>0,_xlpm.tier_filled,F12<>"",_xlpm.status_valid,OR(I12="verified",I12="pending",I12="disputed",I12="unverifiable",I12=""),_xlpm.corr_ok,IF(OR(F12="T4",F12="T5"),J12>0,TRUE),_xlpm.checks,_xlpm.tag_valid+_xlpm.tier_filled+_xlpm.status_valid+_xlpm.corr_ok,ROUND((_xlpm.checks/4)*100,0))) | X12: =IF(AND(U12<>"",V12<>"",W12<>""),ROUND((U12*0.3+V12*0.4+W12*0.3),0),IF(U12<>"",U12,"")) -> 0 | Y12: =IF(B12="","",_xlfn.LET(_xlpm.core_filled,AND(B12<>"",E12<>"",F12<>"",G12<>"",I12<>""),_xlpm.author_ok,OR(L12<>"",M12<>""),_xlpm.rating_ok,O12<>"",_xlpm.corr_ok,IF(OR(F12="T4",F12="T5"),J12>=2,TRUE),_xlpm.quality_ok,V12>=60,_xlpm.composite_ok,X12>=65,_xlpm.gates_pass,AND(_xlpm.core_filled,_xlpm.author_ok,_xlpm.rating_ok,_xlpm.corr_ok,_xlpm.quality_ok,_xlpm.composite_ok),IF(_xlpm.gates_pass,"✅ READY","❌ BLOCKED")))
A13: CLAIM-011 | U13: =IF(COUNTA(A13:S13)=0,"",ROUND((COUNTA(B13:S13)/18)*100,0)) -> 0 | V13: =IF(F13="","",IF(F13="T1",100,IF(F13="T2",80,IF(F13="T3",60,IF(F13="T4",35,IF(F13="T5",15,IF(F13="N",50,0))))))) | W13: =IF(OR(A13="",E13=""),"",_xlfn.LET(_xlpm.tag_valid,COUNTIF(EVIDENCE_TAXONOMY!F13:F55,E13)>0,_xlpm.tier_filled,F13<>"",_xlpm.status_valid,OR(I13="verified",I13="pending",I13="disputed",I13="unverifiable",I13=""),_xlpm.corr_ok,IF(OR(F13="T4",F13="T5"),J13>0,TRUE),_xlpm.checks,_xlpm.tag_valid+_xlpm.tier_filled+_xlpm.status_valid+_xlpm.corr_ok,ROUND((_xlpm.checks/4)*100,0))) | X13: =IF(AND(U13<>"",V13<>"",W13<>""),ROUND((U13*0.3+V13*0.4+W13*0.3),0),IF(U13<>"",U13,"")) -> 0 | Y13: =IF(B13="","",_xlfn.LET(_xlpm.core_filled,AND(B13<>"",E13<>"",F13<>"",G13<>"",I13<>""),_xlpm.author_ok,OR(L13<>"",M13<>""),_xlpm.rating_ok,O13<>"",_xlpm.corr_ok,IF(OR(F13="T4",F13="T5"),J13>=2,TRUE),_xlpm.quality_ok,V13>=60,_xlpm.composite_ok,X13>=65,_xlpm.gates_pass,AND(_xlpm.core_filled,_xlpm.author_ok,_xlpm.rating_ok,_xlpm.corr_ok,_xlpm.quality_ok,_xlpm.composite_ok),IF(_xlpm.gates_pass,"✅ READY","❌ BLOCKED")))
A14: CLAIM-012 | U14: =IF(COUNTA(A14:S14)=0,"",ROUND((COUNTA(B14:S14)/18)*100,0)) -> 0 | V14: =IF(F14="","",IF(F14="T1",100,IF(F14="T2",80,IF(F14="T3",60,IF(F14="T4",35,IF(F14="T5",15,IF(F14="N",50,0))))))) | W14: =IF(OR(A14="",E14=""),"",_xlfn.LET(_xlpm.tag_valid,COUNTIF(EVIDENCE_TAXONOMY!F14:F56,E14)>0,_xlpm.tier_filled,F14<>"",_xlpm.status_valid,OR(I14="verified",I14="pending",I14="disputed",I14="unverifiable",I14=""),_xlpm.corr_ok,IF(OR(F14="T4",F14="T5"),J14>0,TRUE),_xlpm.checks,_xlpm.tag_valid+_xlpm.tier_filled+_xlpm.status_valid+_xlpm.corr_ok,ROUND((_xlpm.checks/4)*100,0))) | X14: =IF(AND(U14<>"",V14<>"",W14<>""),ROUND((U14*0.3+V14*0.4+W14*0.3),0),IF(U14<>"",U14,"")) -> 0 | Y14: =IF(B14="","",_xlfn.LET(_xlpm.core_filled,AND(B14<>"",E14<>"",F14<>"",G14<>"",I14<>""),_xlpm.author_ok,OR(L14<>"",M14<>""),_xlpm.rating_ok,O14<>"",_xlpm.corr_ok,IF(OR(F14="T4",F14="T5"),J14>=2,TRUE),_xlpm.quality_ok,V14>=60,_xlpm.composite_ok,X14>=65,_xlpm.gates_pass,AND(_xlpm.core_filled,_xlpm.author_ok,_xlpm.rating_ok,_xlpm.corr_ok,_xlpm.quality_ok,_xlpm.composite_ok),IF(_xlpm.gates_pass,"✅ READY","❌ BLOCKED")))
A15: CLAIM-013 | U15: =IF(COUNTA(A15:S15)=0,"",ROUND((COUNTA(B15:S15)/18)*100,0)) -> 0 | V15: =IF(F15="","",IF(F15="T1",100,IF(F15="T2",80,IF(F15="T3",60,IF(F15="T4",35,IF(F15="T5",15,IF(F15="N",50,0))))))) | W15: =IF(OR(A15="",E15=""),"",_xlfn.LET(_xlpm.tag_valid,COUNTIF(EVIDENCE_TAXONOMY!F15:F57,E15)>0,_xlpm.tier_filled,F15<>"",_xlpm.status_valid,OR(I15="verified",I15="pending",I15="disputed",I15="unverifiable",I15=""),_xlpm.corr_ok,IF(OR(F15="T4",F15="T5"),J15>0,TRUE),_xlpm.checks,_xlpm.tag_valid+_xlpm.tier_filled+_xlpm.status_valid+_xlpm.corr_ok,ROUND((_xlpm.checks/4)*100,0))) | X15: =IF(AND(U15<>"",V15<>"",W15<>""),ROUND((U15*0.3+V15*0.4+W15*0.3),0),IF(U15<>"",U15,"")) -> 0 | Y15: =IF(B15="","",_xlfn.LET(_xlpm.core_filled,AND(B15<>"",E15<>"",F15<>"",G15<>"",I15<>""),_xlpm.author_ok,OR(L15<>"",M15<>""),_xlpm.rating_ok,O15<>"",_xlpm.corr_ok,IF(OR(F15="T4",F15="T5"),J15>=2,TRUE),_xlpm.quality_ok,V15>=60,_xlpm.composite_ok,X15>=65,_xlpm.gates_pass,AND(_xlpm.core_filled,_xlpm.author_ok,_xlpm.rating_ok,_xlpm.corr_ok,_xlpm.quality_ok,_xlpm.composite_ok),IF(_xlpm.gates_pass,"✅ READY","❌ BLOCKED")))
... A22: CLAIM-020 | U22: =IF(COUNTA(A22:S22)=0,"",ROUND((COUNTA(B22:S22)/18)*100,0)) -> 0 | V22: =IF(F22="","",IF(F22="T1",100,IF(F22="T2",80,IF(F22="T3",60,IF(F22="T4",35,IF(F22="T5",15,IF(F22="N",50,0))))))) | W22: =IF(OR(A22="",E22=""),"",_xlfn.LET(_xlpm.tag_valid,COUNTIF(EVIDENCE_TAXONOMY!F22:F64,E22)>0,_xlpm.tier_filled,F22<>"",_xlpm.status_valid,OR(I22="verified",I22="pending",I22="disputed",I22="unverifiable",I22=""),_xlpm.corr_ok,IF(OR(F22="T4",F22="T5"),J22>0,TRUE),_xlpm.checks,_xlpm.tag_valid+_xlpm.tier_filled+_xlpm.status_valid+_xlpm.corr_ok,ROUND((_xlpm.checks/4)*100,0))) | X22: =IF(AND(U22<>"",V22<>"",W22<>""),ROUND((U22*0.3+V22*0.4+W22*0.3),0),IF(U22<>"",U22,"")) -> 0 | Y22: =IF(B22="","",_xlfn.LET(_xlpm.core_filled,AND(B22<>"",E22<>"",F22<>"",G22<>"",I22<>""),_xlpm.author_ok,OR(L22<>"",M22<>""),_xlpm.rating_ok,O22<>"",_xlpm.corr_ok,IF(OR(F22="T4",F22="T5"),J22>=2,TRUE),_xlpm.quality_ok,V22>=60,_xlpm.composite_ok,X22>=65,_xlpm.gates_pass,AND(_xlpm.core_filled,_xlpm.author_ok,_xlpm.rating_ok,_xlpm.corr_ok,_xlpm.quality_ok,_xlpm.composite_ok),IF(_xlpm.gates_pass,"✅ READY","❌ BLOCKED")))
A24: ── SUMMARY METRICS ──
A25: Total Entries | B25: =COUNTA(B3:B22) -> 0 | C25: Avg Completeness | D25: =IF(COUNTA(U3:U22)=0,"-",ROUND(AVERAGE(U3:U22),0)) -> 0 | E25: Avg Quality | F25: =IFERROR(IF(COUNTA(V3:V22)=0,"-",ROUND(AVERAGE(V3:V22),0)),"-") -> - | G25: Avg Consistency | H25: =IFERROR(IF(COUNTA(W3:W22)=0,"-",ROUND(AVERAGE(W3:W22),0)),"-") -> - | I25: Composite Score | J25: =IF(COUNTA(X3:X22)=0,"-",ROUND(AVERAGE(X3:X22),0)) -> 0 | L25: Promo Ready | M25: =COUNTIF(Y3:Y22,"✅ READY") -> 0 | N25: Blocked | O25: =COUNTIF(Y3:Y22,"❌ BLOCKED") -> 0 | P25: Promo Rate | Q25: =IFERROR(ROUND(M25/(M25+O25)*100,0),"-") -> -
A26: Tier Distribution | B26: ="T1: "&COUNTIF(F3:F22,"T1")&" T2: "&COUNTIF(F3:F22,"T2")&" T3: "&COUNTIF(F3:F22,"T3")&" T4: "&COUNTIF(F3:F22,"T4")&" T5: "&COUNTIF(F3:F22,"T5")&" N: "&COUNTIF(F3:F22,"N") -> T1: 0 T2: 0 T3: 0 T4: 0 T5: 0 N: 0 | E26: Verified | F26: =COUNTIF(I3:I22,"verified") -> 0 | G26: Pending | H26: =COUNTIF(I3:I22,"pending") -> 0 | I26: Disputed | J26: =COUNTIF(I3:I22,"disputed") -> 0

Sheet SCHEMA_MAP
A1: OPENINTEL ↔ SCHEMA.ORG CONVERGENCE MAP | E1: ClaimReview · ItemList · Person · Boolean
A2: OPENINTEL FIELD | B2: SCHEMA.ORG PROPERTY | C2: SCHEMA TYPE | D2: STATUS | E2: CONVERGENCE NOTES | F2: REQUIRED?
A3: ── EXISTING FIELDS (mapped) ──
A4: CLAIM_ID | B4: identifier (Thing) | C4: Text | URL | D4: ✅ MAPPED | E4: Direct match. Our CLAIM-### format is a valid identifier. | F4: YES
A5: CLAIM_TEXT | B5: claimReviewed (ClaimReview) | C5: Text | D5: ✅ MAPPED | E5: Exact match. The specific claim being fact-checked. | F5: YES
A6: CASE_REF | B6: isPartOf (CreativeWork) | C6: CreativeWork | D6: ✅ MAPPED | E6: Links to parent case/investigation. Use case ID from CASE_TYPES sheet. | F6: NO
A7: SOURCE | B7: author (CreativeWork) | C7: Person | Org | D7: ✅ MAPPED | E7: Maps to author. For promotion, should split into AUTHOR_NAME + AUTHOR_ORG (Person schema). | F7: YES
A8: DB_TAG | B8: additionalType (Thing) | C8: Text | URL | D8: ⚡ EXTENDED | E8: Our 38-type taxonomy extends Schema.org. No equivalent in ClaimReview — we're better here. | F8: YES
A9: TIER | B9: reviewRating.ratingValue | C9: Number | D9: ⚡ EXTENDED | E9: Map T1→5, T2→4, T3→3, T4→2, T5→1, N→0 for Schema.org numeric rating. Our tiered system is richer. | F9: YES
A10: URL | B10: url (Thing) | C10: URL | D10: ✅ MAPPED | E10: Direct match. Link to source material. | F10: YES
A11: DATE_ACCESSED | B11: sdDatePublished (CreativeWork) | C11: Date | D11: ⚠️ PARTIAL | E11: Schema.org has datePublished but no dateAccessed. Keep both — add DATE_PUBLISHED for convergence. | F11: NO
A12: VERIFICATION | B12: creativeWorkStatus (CreativeWork) | C12: Text | D12: ⚡ EXTENDED | E12: Our verified/pending/disputed/unverifiable is more specific than Schema.org's generic status field. | F12: YES
A13: CORROBORATION | B13: aggregateRating.ratingCount | C13: Integer | D13: ⚡ EXTENDED | E13: Number of independent sources confirming. Schema.org tracks rating count; we track source corroboration. | F13: NO
A14: NOTES | B14: reviewBody (Review) | C14: Text | D14: ✅ MAPPED | E14: Direct match. Free-text review body / annotation. | F14: NO
A16: ── NEW FIELDS (from Schema.org convergence) ──
A17: AUTHOR_NAME | B17: author.name (Person) | C17: Text | D17: ➕ NEW | E17: Named person who authored the evidence. Required for promotion — anonymous claims flagged. | F17: PROMO
A18: AUTHOR_ORG | B18: author.affiliation (Person) | C18: Text | D18: ➕ NEW | E18: Organization of the author/source. From Person schema affiliation property. | F18: PROMO
A19: ITEM_REVIEWED | B19: itemReviewed (Review) | C19: Thing | D19: ➕ NEW | E19: The specific thing being reviewed (event, document, statement). Google uses this for rich results. | F19: PROMO
A20: REVIEW_RATING | B20: reviewRating.alternateName | C20: Text | D20: ➕ NEW | E20: Human-readable verdict: True / Mostly True / Mixed / Mostly False / False / Unproven. Google ClaimReview label. | F20: PROMO
A21: DATE_PUBLISHED | B21: datePublished (CreativeWork) | C21: Date | D21: ➕ NEW | E21: When the original claim/source was published. Distinct from DATE_ACCESSED (when you retrieved it). | F21: PROMO
A22: DATE_REVIEWED | B22: dateModified (CreativeWork) | C22: Date | D22: ➕ NEW | E22: When this evidence review was last updated. Signals freshness to search engines. | F22: NO
A23: POSITIVE_NOTES | B23: positiveNotes (Review) | C23: ItemList | Text | D23: ➕ NEW | E23: Strengths of this evidence (structured pro list). Uses ItemList schema for ordered items. | F23: NO
A24: NEGATIVE_NOTES | B24: negativeNotes (Review) | C24: ItemList | Text | D24: ➕ NEW | E24: Weaknesses of this evidence (structured con list). Uses ItemList schema for ordered items. | F24: NO
A26: ── PROMOTION GATE (required for main web page) ──
A27: Rule | B27: Check | D27: Weight | E27: Rationale
A28: 1. Schema.org Required Fields | B28: CLAIM_TEXT + DB_TAG + TIER + URL + VERIFICATION all filled | D28: PASS/FAIL | E28: Hard gate — must pass. These are the minimum for a valid ClaimReview structured data entry.
A29: 2. Author Attribution | B29: AUTHOR_NAME or AUTHOR_ORG is non-empty | D29: PASS/FAIL | E29: Google requires author for ClaimReview rich results. Anonymous claims cannot be promoted.
A30: 3. Review Rating Present | B30: REVIEW_RATING is one of: True/Mostly True/Mixed/Mostly False/False/Unproven | D30: PASS/FAIL | E30: Google ClaimReview requires a textual rating. This is the human-readable verdict.
A31: 4. Evidence Quality Threshold | B31: Quality score (TIER weight) ≥ 60% | D31: 0.2 | E31: T1–T3 evidence passes automatically. T4–T5 need corroboration to qualify.
A32: 5. Consistency Check | B32: Consistency score ≥ 75% | D32: 0.2 | E32: DB_TAG must exist in taxonomy, tier within range, verification status valid.
A33: 6. Corroboration for Weak Sources | B33: If TIER = T4 or T5, CORROBORATION must be ≥ 2 | D33: PASS/FAIL | E33: Weak sources cannot be promoted without independent corroboration. Prevents single-source claims on main page.
A34: 7. Composite Score | B34: Overall composite ≥ 65% | D34: 0.6 | E34: Final quality gate. Weighted composite of completeness, quality, and consistency must hit threshold.

Sheet JSONLD_TEMPLATES
A1: JSON-LD STRUCTURED DATA TEMPLATES | D1: ClaimReview + Dataset · Inject into <head> of SPA case pages
A2: TEMPLATE | B2: JSON-LD CODE | D2: NOTES / FIELD MAPPING
A3: ── 1. ClaimReview (per evidence entry) ──
A4: ClaimReview (one per evidence entry) | B4: <script type="application/ld+json"> { "@context": "https://schema.org", "@type": "ClaimReview", "url": "https://openintel.org/cases/{{slug}}", "claimReviewed": "{{claim_text}}", "author": { "@type": "Organization", "name": "OpenIntel", "url": "https://openintel.org" }, "reviewRating": { "@type": "Rating", "ratingValue": {{tier_numeric}}, "bestRating": 5, "worstRating": 0, "alternateName": "{{review_rating}}" }, "itemReviewed": { "@type": "CreativeWork", "name": "{{item_reviewed}}", "author": { "@type": "Person", "name": "{{author_name}}", "affiliation": { "@type": "Organization", "name": "{{author_org}}" } }, "datePublished": "{{date_published}}", "appearance": [ { "@type": "WebPage", "url": "{{evidence_url}}" } ] }, "datePublished": "{{date_reviewed}}", "reviewBody": "Evidence type: {{db_tag}} (Tier {{tier}}). {{notes}}", "positiveNotes": { "@type": "ItemList", "itemListElement": [ { "@type": "ListItem", "position": 1, "name": "{{positive_notes}}" } ] }, "negativeNotes": { "@type": "ItemList", "itemListElement": [ { "@type": "ListItem", "position": 1, "name": "{{negative_notes}}" } ] }, "additionalType": "https://openintel.org/taxonomy/{{db_tag}}" } </script> | D4: FIELD MAP: {{slug}} ← case slug from API {{claim_text}} ← CLAIM_TEXT (col B) {{tier_numeric}} ← TIER mapped: T1=5, T2=4, T3=3, T4=2, T5=1, N=0 {{review_rating}} ← REVIEW_RATING (col O) {{item_reviewed}} ← ITEM_REVIEWED (col N) {{author_name}} ← AUTHOR_NAME (col L) {{author_org}} ← AUTHOR_ORG (col M) {{date_published}} ← DATE_PUBLISHED (col P) ISO 8601 {{evidence_url}} ← URL (col G) {{date_reviewed}} ← DATE_REVIEWED (col Q) ISO 8601 {{db_tag}} ← DB_TAG (col E) {{tier}} ← TIER (col F) {{notes}} ← NOTES (col K) {{positive_notes}} ← POSITIVE_NOTES (col R) {{negative_notes}} ← NEGATIVE_NOTES (col S) NOTE: Only inject for rows where PROMO GATE = ✅ READY Omit positiveNotes/negativeNotes blocks if empty. For multiple evidence items per case, emit multiple ClaimReview blocks.
A6: ── 2. Dataset (per API endpoint) ──
A7: Dataset (site-wide, on /api or /research index) | B7: <script type="application/ld+json"> { "@context": "https://schema.org", "@type": "Dataset", "name": "OpenIntel Evidence Taxonomy Dataset", "description": "Structured evidence grading database using a 38-type, 6-tier taxonomy for evaluating claims. Each entry is typed, tiered, and scored using the OpenIntel Evidence Classification System.", "url": "https://openintel.org/api/evidence", "license": "https://creativecommons.org/licenses/by-sa/4.0/", "creator": { "@type": "Organization", "name": "OpenIntel", "url": "https://openintel.org" }, "datePublished": "{{dataset_publish_date}}", "dateModified": "{{dataset_modified_date}}", "keywords": [ "evidence taxonomy", "fact-checking", "claim review", "structured evidence", "OSINT", "evidence grading" ], "measurementTechnique": "6-tier evidence classification (T1-T5 + Negative)", "variableMeasured": [ { "@type": "PropertyValue", "name": "Evidence Tier", "description": "Source strength rating from T1 (Primary/Strongest) to T5 (Weakest), plus N (Negative Evidence)", "minValue": 0, "maxValue": 5 }, { "@type": "PropertyValue", "name": "Evidence Type", "description": "One of 38 classified evidence types (e.g., declass_gov, court_record, peer_reviewed)" }, { "@type": "PropertyValue", "name": "Verification Status", "description": "One of: verified, pending, disputed, unverifiable" }, { "@type": "PropertyValue", "name": "Corroboration Count", "description": "Number of independent sources confirming this evidence" } ], "distribution": [ { "@type": "DataDownload", "encodingFormat": "application/json", "contentUrl": "https://openintel.org/api/evidence.json" }, { "@type": "DataDownload", "encodingFormat": "text/yaml", "contentUrl": "https://openintel.org/api/evidence.yaml" } ] } </script> | D7: DATASET SCHEMA NOTES: This goes on the /api index page or /research page. Signals to Google that this is structured research data, not editorial content. variableMeasured maps your 4 scoring dimensions: • Evidence Tier (T1-T5+N) → ratingValue 0-5 • Evidence Type (38 db_tags) → additionalType • Verification Status (4 states) → creativeWorkStatus • Corroboration Count → aggregateRating.ratingCount distribution offers both JSON and YAML downloads. Update encodingFormat if you add CSV export. {{dataset_publish_date}} ← first publish date {{dataset_modified_date}} ← last API data change License: CC BY-SA 4.0 recommended for open research. Change to appropriate license for your use case.
A9: ── 3. SPA Injection Code ──
A10: injectClaimReviewLD() (call in case detail component) | B10: // SPA helper: serialize API response → JSON-LD and inject into <head> // Call this in your case detail page component (onMount / useEffect) const TIER_MAP = { T1: 5, T2: 4, T3: 3, T4: 2, T5: 1, N: 0 }; function injectClaimReviewLD(caseData) { // caseData = API response for a single case // { slug, title, status, evidence: [{ claim_text, db_tag, tier, url, ... }] } const claimReviews = caseData.evidence .filter(e => e.promo_gate === 'READY') // Only promoted entries .map(e => ({ '@context': 'https://schema.org', '@type': 'ClaimReview', url: `https://openintel.org/cases/${caseData.slug}`, claimReviewed: e.claim_text, author: { '@type': 'Organization', name: 'OpenIntel', url: 'https://openintel.org' }, reviewRating: { '@type': 'Rating', ratingValue: TIER_MAP[e.tier] || 0, bestRating: 5, worstRating: 0, alternateName: e.review_rating }, itemReviewed: { '@type': 'CreativeWork', name: e.item_reviewed, author: { '@type': 'Person', name: e.author_name, ...(e.author_org && { affiliation: { '@type': 'Organization', name: e.author_org } }) }, datePublished: e.date_published, appearance: [{ '@type': 'WebPage', url: e.url }] }, datePublished: e.date_reviewed || new Date().toISOString().split('T')[0], reviewBody: `Evidence type: ${e.db_tag} (Tier ${e.tier}). ${e.notes || ''}`.trim(), additionalType: `https://openintel.org/taxonomy/${e.db_tag}`, ...(e.positive_notes && { positiveNotes: { '@type': 'ItemList', itemListElement: [{ '@type': 'ListItem', position: 1, name: e.positive_notes }] } }), ...(e.negative_notes && { negativeNotes: { '@type': 'ItemList', itemListElement: [{ '@type': 'ListItem', position: 1, name: e.negative_notes }] } }) })); // Remove existing LD+JSON scripts (avoid duplicates on SPA nav) document.querySelectorAll('script[data-openintel-ld]') .forEach(el => el.remove()); // Inject each ClaimReview as a separate script tag claimReviews.forEach((review, i) => { const script = document.createElement('script'); script.type = 'application/ld+json'; script.setAttribute('data-openintel-ld', `claim-${i}`); script.textContent = JSON.stringify(review, null, 2); document.head.appendChild(script); }); return claimReviews.length; } | D10: IMPLEMENTATION NOTES: 1. This function takes your existing API response object. The data is already there — status, slug, title, evidence array. No new API work needed. 2. Only entries where promo_gate === 'READY' get serialized into JSON-LD. The rest are filtered out. This is your quality gate in action. 3. Call in your case detail component: • React: useEffect(() => { injectClaimReviewLD(data); }, [data]) • Vue: onMounted(() => injectClaimReviewLD(data)) • Svelte: onMount(() => injectClaimReviewLD(data)) 4. The data-openintel-ld attribute lets us clean up on SPA navigation (no stale LD+JSON from previous page). 5. additionalType links to your taxonomy namespace: https://openintel.org/taxonomy/{{db_tag}} This is where you're better than ClaimReview — your 38-type system gives granularity they can't match. 6. appearance[] in itemReviewed links to the actual evidence source URL. Google uses this for the 'Claim appears in:' display in search results. 7. For SSR (Next.js/Nuxt): render the script tags server-side instead of DOM injection. Same JSON, just in the template <head> block. API FIELDS NEEDED (add to response if missing): • promo_gate: string ('READY' | 'BLOCKED') • review_rating: string • author_name: string • author_org: string • item_reviewed: string • date_published: string (ISO 8601) • date_reviewed: string (ISO 8601) • positive_notes: string | null • negative_notes: string | null
A12: ── 4. API Response → JSON-LD Field Map ──
A13: API Field | B13: JSON-LD Path | C13: Required | D13: Transform
A14: slug | B14: url (appended to base URL) | C14: ✅ | D14: `https://openintel.org/cases/${slug}`
A15: evidence[].claim_text | B15: claimReviewed | C15: ✅ | D15: Direct passthrough. Already in API response.
A16: evidence[].tier | B16: reviewRating.ratingValue | C16: ✅ | D16: TIER_MAP lookup: { T1:5, T2:4, T3:3, T4:2, T5:1, N:0 }
A17: evidence[].review_rating | B17: reviewRating.alternateName | C17: ✅ | D17: Direct passthrough. True/Mostly True/Mixed/Mostly False/False/Unproven
A18: evidence[].db_tag | B18: additionalType + reviewBody | C18: ✅ | D18: Prefix with namespace: `https://openintel.org/taxonomy/${db_tag}`
A19: evidence[].url | B19: itemReviewed.appearance[].url | C19: ✅ | D19: Direct passthrough. Links to the actual source material.
A20: evidence[].author_name | B20: itemReviewed.author.name | C20: PROMO | D20: NEW FIELD — add to API response. Required for promotion.
A21: evidence[].author_org | B21: itemReviewed.author.affiliation.name | C21: PROMO | D21: NEW FIELD — add to API response. Optional if author_name present.
A22: evidence[].item_reviewed | B22: itemReviewed.name | C22: PROMO | D22: NEW FIELD — add to API response. The thing being fact-checked.
A23: evidence[].promo_gate | B23: (filter gate — not in JSON-LD) | C23: GATE | D23: NEW FIELD — computed server-side from scoring formulas. 'READY' entries get LD, others don't.

Sheet PIPELINE_SPEC
A1: OPENINTEL FULL PIPELINE SPEC | B1: Postgres → Cloudflare Workers → Web Form → Auto-Promote → JSON-LD
A2: SECTION | B2: SPEC | C2: NOTES
A3: ── 1. POSTGRES SCHEMA ──
A4: evidence_taxonomy (reference table) | B4: CREATE TABLE evidence_taxonomy ( id SERIAL PRIMARY KEY, type_num INT NOT NULL UNIQUE, tier VARCHAR(2) NOT NULL, -- T1, T2, T3, T4, T5, N evidence_type VARCHAR(100) NOT NULL, description TEXT, examples TEXT, db_tag VARCHAR(30) NOT NULL UNIQUE, tier_range VARCHAR(10), tier_weight DECIMAL(3,2) NOT NULL, -- T1=1.00, T2=0.80, T3=0.60, T4=0.35, T5=0.15, N=0.50 created_at TIMESTAMPTZ DEFAULT NOW() ); -- Seed from EVIDENCE_TAXONOMY sheet (38 rows) INSERT INTO evidence_taxonomy (type_num, tier, evidence_type, db_tag, tier_range, tier_weight) VALUES (1, 'T1', 'Declassified Government Documents', 'declass_gov', 'T1-T2', 1.00), (2, 'T1', 'Congressional/Parliamentary Records', 'congress_record', 'T1-T2', 1.00), (3, 'T1', 'Court Records', 'court_record', 'T1', 1.00), -- ... (38 rows from your EVIDENCE_TAXONOMY sheet) (38, 'N', 'Classification/Redaction Patterns', 'redaction_pattern', 'ALL', 0.50); | C4: Reference table. Seed once from the EVIDENCE_TAXONOMY sheet. tier_weight drives the quality score calculation server-side. db_tag is the foreign key that evidence_entries references.
A6: evidence_entries (main data table) | B6: CREATE TABLE evidence_entries ( id UUID PRIMARY KEY DEFAULT gen_random_uuid(), claim_id VARCHAR(20) NOT NULL, -- CLAIM-001 format claim_text TEXT NOT NULL, -- schema: claimReviewed case_ref VARCHAR(50), -- FK to cases table / CASE_TYPES source TEXT NOT NULL, -- schema: author db_tag VARCHAR(30) NOT NULL -- FK to evidence_taxonomy REFERENCES evidence_taxonomy(db_tag), tier VARCHAR(2) NOT NULL -- T1, T2, T3, T4, T5, N CHECK (tier IN ('T1','T2','T3','T4','T5','N')), url TEXT NOT NULL, -- schema: url date_accessed DATE, -- when source was accessed verification VARCHAR(15) NOT NULL -- schema: creativeWorkStatus CHECK (verification IN ('verified','pending','disputed','unverifiable')), corroboration INT DEFAULT 0, -- schema: aggregateRating.ratingCount notes TEXT, -- schema: reviewBody -- Schema.org convergence fields author_name TEXT, -- schema: author.name (Person) author_org TEXT, -- schema: author.affiliation item_reviewed TEXT, -- schema: itemReviewed review_rating VARCHAR(20) -- schema: reviewRating.alternateName CHECK (review_rating IN ('True','Mostly True','Mixed','Mostly False','False','Unproven')), date_published DATE, -- schema: datePublished date_reviewed DATE, -- schema: dateModified positive_notes TEXT, -- schema: positiveNotes negative_notes TEXT, -- schema: negativeNotes -- Computed scores (set by trigger / worker) score_completeness INT, -- 0-100 score_quality INT, -- 0-100 score_consistency INT, -- 0-100 score_composite INT, -- 0-100 promo_gate VARCHAR(10) DEFAULT 'BLOCKED' -- 'READY' or 'BLOCKED' CHECK (promo_gate IN ('READY','BLOCKED')), -- Staging status VARCHAR(15) DEFAULT 'draft' -- draft -> staged -> promoted -> archived CHECK (status IN ('draft','staged','promoted','archived')), submitted_by TEXT, -- contributor identifier submitted_at TIMESTAMPTZ DEFAULT NOW(), promoted_at TIMESTAMPTZ, -- when entry went live created_at TIMESTAMPTZ DEFAULT NOW(), updated_at TIMESTAMPTZ DEFAULT NOW() ); CREATE INDEX idx_entries_db_tag ON evidence_entries(db_tag); CREATE INDEX idx_entries_tier ON evidence_entries(tier); CREATE INDEX idx_entries_promo ON evidence_entries(promo_gate); CREATE INDEX idx_entries_status ON evidence_entries(status); CREATE INDEX idx_entries_case ON evidence_entries(case_ref); | C6: Main table. Maps 1:1 to EVIDENCE_ENTRY sheet columns. All 19 user fields + 5 computed scores + staging fields. db_tag FK enforces taxonomy validity (same as the Excel COUNTIF check). CHECK constraints replicate the dropdown validations from the sheet. promo_gate is computed server-side (see scoring trigger below). status flow: draft → staged → promoted → archived draft: just saved, not scored yet staged: scored, waiting for review promoted: passed gate, live on site, gets JSON-LD archived: taken down / superseded UUID primary key for API-friendly IDs. Timestamps for audit trail.
A8: scoring trigger (auto-compute on insert/update) | B8: CREATE OR REPLACE FUNCTION compute_evidence_scores() RETURNS TRIGGER AS $$ DECLARE v_total_fields INT := 18; v_filled INT := 0; v_quality INT := 0; v_consistency INT := 0; v_tag_valid BOOLEAN; v_tier_weight DECIMAL; BEGIN -- 1. COMPLETENESS: count non-null, non-empty fields / 18 v_filled := ( (CASE WHEN COALESCE(NEW.claim_text,'') != '' THEN 1 ELSE 0 END) + (CASE WHEN COALESCE(NEW.case_ref,'') != '' THEN 1 ELSE 0 END) + (CASE WHEN COALESCE(NEW.source,'') != '' THEN 1 ELSE 0 END) + (CASE WHEN COALESCE(NEW.db_tag,'') != '' THEN 1 ELSE 0 END) + (CASE WHEN COALESCE(NEW.tier,'') != '' THEN 1 ELSE 0 END) + (CASE WHEN COALESCE(NEW.url,'') != '' THEN 1 ELSE 0 END) + (CASE WHEN NEW.date_accessed IS NOT NULL THEN 1 ELSE 0 END) + (CASE WHEN COALESCE(NEW.verification,'') != '' THEN 1 ELSE 0 END) + (CASE WHEN COALESCE(NEW.corroboration, 0) > 0 THEN 1 ELSE 0 END) + (CASE WHEN COALESCE(NEW.notes,'') != '' THEN 1 ELSE 0 END) + (CASE WHEN COALESCE(NEW.author_name,'') != '' THEN 1 ELSE 0 END) + (CASE WHEN COALESCE(NEW.author_org,'') != '' THEN 1 ELSE 0 END) + (CASE WHEN COALESCE(NEW.item_reviewed,'') != '' THEN 1 ELSE 0 END) + (CASE WHEN COALESCE(NEW.review_rating,'') != '' THEN 1 ELSE 0 END) + (CASE WHEN NEW.date_published IS NOT NULL THEN 1 ELSE 0 END) + (CASE WHEN NEW.date_reviewed IS NOT NULL THEN 1 ELSE 0 END) + (CASE WHEN COALESCE(NEW.positive_notes,'') != '' THEN 1 ELSE 0 END) + (CASE WHEN COALESCE(NEW.negative_notes,'') != '' THEN 1 ELSE 0 END) ); NEW.score_completeness := ROUND((v_filled::DECIMAL / v_total_fields) * 100); -- 2. QUALITY: tier weight lookup SELECT tier_weight INTO v_tier_weight FROM evidence_taxonomy WHERE db_tag = NEW.db_tag; NEW.score_quality := COALESCE(ROUND(v_tier_weight * 100), 0); -- 3. CONSISTENCY: tag valid + tier filled + status valid + corroboration check SELECT EXISTS(SELECT 1 FROM evidence_taxonomy WHERE db_tag = NEW.db_tag) INTO v_tag_valid; v_consistency := ( (CASE WHEN v_tag_valid THEN 1 ELSE 0 END) + (CASE WHEN NEW.tier IS NOT NULL THEN 1 ELSE 0 END) + (CASE WHEN NEW.verification IN ('verified','pending','disputed','unverifiable') THEN 1 ELSE 0 END) + (CASE WHEN NEW.tier IN ('T4','T5') AND COALESCE(NEW.corroboration,0) < 1 THEN 0 ELSE 1 END) ); NEW.score_consistency := ROUND((v_consistency::DECIMAL / 4) * 100); -- 4. COMPOSITE: completeness*0.3 + quality*0.4 + consistency*0.3 NEW.score_composite := ROUND( NEW.score_completeness * 0.3 + NEW.score_quality * 0.4 + NEW.score_consistency * 0.3 ); -- 5. PROMOTION GATE IF ( COALESCE(NEW.claim_text,'') != '' AND COALESCE(NEW.db_tag,'') != '' AND COALESCE(NEW.tier,'') != '' AND COALESCE(NEW.url,'') != '' AND COALESCE(NEW.verification,'') != '' AND (COALESCE(NEW.author_name,'') != '' OR COALESCE(NEW.author_org,'') != '') AND COALESCE(NEW.review_rating,'') != '' AND (NEW.tier NOT IN ('T4','T5') OR COALESCE(NEW.corroboration,0) >= 2) AND NEW.score_quality >= 60 AND NEW.score_composite >= 65 ) THEN NEW.promo_gate := 'READY'; -- Auto-stage if draft IF NEW.status = 'draft' THEN NEW.status := 'staged'; END IF; ELSE NEW.promo_gate := 'BLOCKED'; END IF; NEW.updated_at := NOW(); RETURN NEW; END; $$ LANGUAGE plpgsql; CREATE TRIGGER trg_evidence_scores BEFORE INSERT OR UPDATE ON evidence_entries FOR EACH ROW EXECUTE FUNCTION compute_evidence_scores(); | C8: This trigger replicates EXACTLY the same scoring logic from your Excel formulas: Excel col U (COMPLETENESS) = v_filled / 18 * 100 Excel col V (QUALITY) = tier weight lookup Excel col W (CONSISTENCY) = 4-check validation Excel col X (COMPOSITE) = weighted average Excel col Y (PROMO GATE) = 7-rule check Fires on every INSERT and UPDATE. Key behavior: • If an entry passes the promo gate and is still 'draft', it auto-advances to 'staged' • Promotion from 'staged' → 'promoted' is a separate manual/API action (see Worker endpoint) • Scores are always recomputed, so editing a promoted entry can un-promote it The gate rules are identical to the SCHEMA_MAP promotion gate: 1. Core fields filled 2. Author attribution 3. Review rating present 4. Corroboration for T4/T5 ≥ 2 5. Quality ≥ 60% 6. Composite ≥ 65%
A10: ── 2. CLOUDFLARE WORKERS API ──
A11: POST /api/evidence (submit new entry) | B11: // Cloudflare Worker: POST /api/evidence // Accepts form submission, validates, inserts into Postgres via Hyperdrive export async function onRequestPost({ request, env }) { const body = await request.json(); // 1. Server-side validation (mirrors Excel dropdowns) const VALID_TIERS = ['T1','T2','T3','T4','T5','N']; const VALID_VERIF = ['verified','pending','disputed','unverifiable']; const VALID_RATING = ['True','Mostly True','Mixed','Mostly False','False','Unproven']; const errors = []; if (!body.claim_text?.trim()) errors.push('claim_text is required'); if (!body.db_tag?.trim()) errors.push('db_tag is required'); if (!VALID_TIERS.includes(body.tier)) errors.push('tier must be T1-T5 or N'); if (!body.url?.trim()) errors.push('url is required'); if (!VALID_VERIF.includes(body.verification)) errors.push('invalid verification status'); if (body.review_rating && !VALID_RATING.includes(body.review_rating)) errors.push('invalid review_rating'); if (errors.length > 0) { return Response.json({ ok: false, errors }, { status: 400 }); } // 2. Insert via Hyperdrive (Postgres trigger auto-computes scores) const db = env.HYPERDRIVE.connect(); const result = await db.query( `INSERT INTO evidence_entries ( claim_id, claim_text, case_ref, source, db_tag, tier, url, date_accessed, verification, corroboration, notes, author_name, author_org, item_reviewed, review_rating, date_published, date_reviewed, positive_notes, negative_notes, submitted_by ) VALUES ($1,$2,$3,$4,$5,$6,$7,$8,$9,$10,$11,$12,$13,$14,$15,$16,$17,$18,$19,$20) RETURNING id, promo_gate, status, score_composite`, [ body.claim_id || `CLAIM-${Date.now()}`, body.claim_text, body.case_ref, body.source, body.db_tag, body.tier, body.url, body.date_accessed, body.verification, body.corroboration || 0, body.notes, body.author_name, body.author_org, body.item_reviewed, body.review_rating, body.date_published, body.date_reviewed, body.positive_notes, body.negative_notes, body.submitted_by || 'anonymous' ] ); const entry = result.rows[0]; // 3. Return result with scoring feedback return Response.json({ ok: true, id: entry.id, promo_gate: entry.promo_gate, status: entry.status, score: entry.score_composite, message: entry.promo_gate === 'READY' ? 'Entry scored and staged for promotion.' : 'Entry saved as draft. Fill required fields to qualify for promotion.' }, { status: 201 }); } | C11: SUBMIT ENDPOINT Flow: 1. Form posts JSON to Worker 2. Server-side validation (same rules as Excel dropdowns) 3. Insert into Postgres via Hyperdrive 4. Trigger auto-computes all 5 scores 5. Returns promo_gate status immediately The user sees instant feedback: • 'Entry scored and staged for promotion' if it passes • 'Fill required fields to qualify' if it doesn't They never see the scores directly — just the gate result. Same stealth scoring as the Excel sheet. Claim IDs auto-generate if not provided. Env bindings needed: • HYPERDRIVE: Cloudflare Hyperdrive binding to your Postgres
A13: GET /api/evidence (list + filter) | B13: // GET /api/evidence?tier=T1&status=promoted&limit=50 export async function onRequestGet({ request, env }) { const url = new URL(request.url); const tier = url.searchParams.get('tier'); const status = url.searchParams.get('status') || 'promoted'; const db_tag = url.searchParams.get('db_tag'); const limit = Math.min(parseInt(url.searchParams.get('limit') || '50'), 200); const offset = parseInt(url.searchParams.get('offset') || '0'); let query = 'SELECT * FROM evidence_entries WHERE 1=1'; const params = []; let i = 1; if (tier) { query += ` AND tier = $${i++}`; params.push(tier); } if (status) { query += ` AND status = $${i++}`; params.push(status); } if (db_tag) { query += ` AND db_tag = $${i++}`; params.push(db_tag); } query += ` ORDER BY score_composite DESC, created_at DESC LIMIT $${i++} OFFSET $${i++}`; params.push(limit, offset); const db = env.HYPERDRIVE.connect(); const result = await db.query(query, params); // Add JSON-LD for promoted entries const entries = result.rows.map(row => ({ ...row, // Strip score columns from public response score_completeness: undefined, score_quality: undefined, score_consistency: undefined, score_composite: undefined, jsonld: row.promo_gate === 'READY' ? buildClaimReviewLD(row) : null })); return Response.json({ ok: true, entries, count: entries.length }); } | C13: LIST ENDPOINT Default: returns only promoted entries Filters: tier, status, db_tag Sort: composite score DESC Score columns are STRIPPED from public response. Users see the data + the promo_gate flag but never the numeric scores. The jsonld field contains pre-built ClaimReview JSON-LD for each promoted entry. Your SPA can inject this directly — no client-side serialization needed. For the YAML export endpoint, add: GET /api/evidence.yaml (same query, serialize as YAML)
A15: POST /api/evidence/:id/promote (manual promotion) | B15: // POST /api/evidence/:id/promote // Moves a staged entry to promoted (live on site) export async function onRequestPost({ params, env }) { const db = env.HYPERDRIVE.connect(); // Only promote if gate is READY and status is staged const result = await db.query( `UPDATE evidence_entries SET status = 'promoted', promoted_at = NOW(), updated_at = NOW() WHERE id = $1 AND promo_gate = 'READY' AND status = 'staged' RETURNING id, claim_id, promo_gate, status`, [params.id] ); if (result.rows.length === 0) { return Response.json({ ok: false, error: 'Entry not found, not staged, or promo gate is BLOCKED' }, { status: 400 }); } // Purge Cloudflare cache for this case page // (so JSON-LD updates immediately) await env.CACHE.purge({ tags: [`case-${result.rows[0].case_ref}`] }); return Response.json({ ok: true, entry: result.rows[0], message: 'Entry promoted to live site. JSON-LD will be injected on next page load.' }); } | C15: PROMOTE ENDPOINT The gate between 'staged' and 'promoted' (live on site). Double-checks: • promo_gate must be 'READY' • status must be 'staged' Both must be true. Even if someone calls this endpoint directly, a BLOCKED entry can't be promoted. Optional: purge Cloudflare cache so the JSON-LD shows up immediately on the case page. This is the manual step. You could also set up a cron Worker to auto-promote all 'staged' + 'READY' entries on a schedule.
A17: ── 3. HTML FORM TEMPLATE ──
A18: Evidence Entry Form (Schema.org microdata baked in) | B18: <form id="evidence-form" itemscope itemtype="https://schema.org/ClaimReview" method="POST" action="/api/evidence"> <input type="hidden" name="@context" value="https://schema.org" /> <input type="hidden" name="@type" value="ClaimReview" /> <!-- CORE FIELDS --> <fieldset> <legend>Evidence Details</legend> <label for="claim_text">Claim Being Evaluated *</label> <textarea id="claim_text" name="claim_text" required itemprop="claimReviewed" rows="3" placeholder="The specific claim you are evaluating..."></textarea> <label for="source">Source *</label> <input type="text" id="source" name="source" required placeholder="Where does this evidence come from?" /> <label for="db_tag">Evidence Type *</label> <select id="db_tag" name="db_tag" required itemprop="additionalType"> <option value="">Select evidence type...</option> <optgroup label="T1 — Primary Sources (Strongest)"> <option value="declass_gov">Declassified Government Documents</option> <option value="congress_record">Congressional/Parliamentary Records</option> <option value="court_record">Court Records</option> <option value="official_admit">Official Admissions/Apologies</option> <option value="leaked_doc">Leaked Documents</option> <option value="peer_reviewed">Scientific/Peer-Reviewed Studies</option> <option value="financial_record">Financial Records</option> <option value="forensic">Physical/Forensic Evidence</option> </optgroup> <optgroup label="T2 — Secondary Sources (Supporting)"> <option value="invest_journalism">Investigative Journalism</option> <option value="witness_named">Witness Testimony (Named)</option> <option value="whistleblower">Whistleblower Disclosures</option> <option value="academic_research">Academic Research/Analysis</option> <option value="verified_media">Photographic/Video Evidence (Verified)</option> <option value="foia_response">FOIA Request Responses</option> <option value="audit_report">Audit Reports</option> </optgroup> <optgroup label="T3 — Tertiary Sources (Contextual)"> <option value="stat_pattern">Statistical/Pattern Analysis</option> <option value="circumstantial">Circumstantial Evidence Chains</option> <option value="historical_prec">Historical Precedent</option> <option value="expert_opinion">Expert Opinion (Named)</option> <option value="contemp_news">Contemporaneous News Reports</option> <option value="correspondence">Correspondence/Communications</option> </optgroup> <optgroup label="T4 — Weak Sources (Requires Corroboration)"> <option value="anon_source">Anonymous Sources</option> <option value="hearsay">Secondhand/Hearsay Accounts</option> <option value="unverified_doc">Unverified Documents</option> <option value="confession">Confession/Deathbed Statement</option> <option value="uncontrolled_pattern">Pattern Recognition Without Controls</option> <option value="archived_content">Archived/Deleted Content</option> <option value="documentary_claim">Documentary Film Claims</option> </optgroup> <optgroup label="T5 — Weakest Sources (Flag but Don't Dismiss)"> <option value="single_source">Single-Source Claims</option> <option value="anon_post">Anonymous Internet Posts</option> <option value="channeled">Channeled/Psychic/Revelatory Material</option> <option value="unverifiable">Unverifiable by Design</option> <option value="circular_ref">Circular/Self-Referencing</option> <option value="ai_generated">AI-Generated/Manipulated Content</option> </optgroup> <optgroup label="N — Negative Evidence (Absence as Data)"> <option value="conspic_absence">Conspicuous Absence</option> <option value="suppression">Suppression Evidence</option> <option value="non_denial">Non-Denial Denials</option> <option value="redaction_pattern">Classification/Redaction Patterns</option> </optgroup> </select> <label for="tier">Evidence Tier *</label> <select id="tier" name="tier" required> <option value="">Select tier...</option> <option value="T1">T1 — Primary (Strongest)</option> <option value="T2">T2 — Secondary (Supporting)</option> <option value="T3">T3 — Tertiary (Contextual)</option> <option value="T4">T4 — Weak (Requires Corroboration)</option> <option value="T5">T5 — Weakest (Flag but Don't Dismiss)</option> <option value="N">N — Negative Evidence (Absence as Data)</option> </select> <label for="url">Source URL *</label> <input type="url" id="url" name="url" required itemprop="url" placeholder="https://..." /> <label for="verification">Verification Status *</label> <select id="verification" name="verification" required> <option value="">Select status...</option> <option value="verified">Verified</option> <option value="pending">Pending</option> <option value="disputed">Disputed</option> <option value="unverifiable">Unverifiable</option> </select> <label for="corroboration">Independent Corroboration Count</label> <input type="number" id="corroboration" name="corroboration" min="0" value="0" /> <label for="notes">Notes</label> <textarea id="notes" name="notes" rows="2" itemprop="reviewBody" placeholder="Additional context or annotations..."></textarea> </fieldset> <!-- SCHEMA.ORG FIELDS (for promotion) --> <fieldset> <legend>Author &amp; Review Details (needed for web publication)</legend> <label for="author_name">Author Name</label> <input type="text" id="author_name" name="author_name" itemprop="author" placeholder="Named person who authored this evidence" /> <label for="author_org">Author Organization</label> <input type="text" id="author_org" name="author_org" placeholder="Organization (e.g. Washington Post, MIT, CIA)" /> <label for="item_reviewed">Item Reviewed</label> <input type="text" id="item_reviewed" name="item_reviewed" itemprop="itemReviewed" placeholder="What specific thing is being fact-checked?" /> <label for="review_rating">Review Rating</label> <select id="review_rating" name="review_rating"> <option value="">Select verdict...</option> <option value="True">True</option> <option value="Mostly True">Mostly True</option> <option value="Mixed">Mixed</option> <option value="Mostly False">Mostly False</option> <option value="False">False</option> <option value="Unproven">Unproven</option> </select> <label for="date_published">Date Published</label> <input type="date" id="date_published" name="date_published" /> <label for="positive_notes">Strengths of Evidence</label> <textarea id="positive_notes" name="positive_notes" rows="2" placeholder="What makes this evidence strong?"></textarea> <label for="negative_notes">Weaknesses of Evidence</label> <textarea id="negative_notes" name="negative_notes" rows="2" placeholder="Caveats, limitations, concerns?"></textarea> </fieldset> <button type="submit">Submit Evidence</button> </form> | C18: FORM STRUCTURE Two fieldsets: 1. Core Evidence Details (required) 2. Author & Review (needed for promotion) The form DOES NOT show scoring fields. Users fill in evidence naturally. The server-side trigger scores it and they get back a simple pass/fail. Schema.org microdata is baked into the HTML: • itemscope itemtype="ClaimReview" on <form> • itemprop on key fields • This means even the FORM PAGE itself is structured data The <select> for db_tag uses <optgroup> to mirror your 6-tier taxonomy structure. Users see the hierarchy. All required fields marked with * match the promo gate hard requirements. The form posts JSON to /api/evidence (Worker endpoint above). For SPA: replace form action with fetch() call and handle the response JSON (promo_gate status).
A20: ── 4. STAGING PIPELINE ──
A21: Status flow diagram | B21: EVIDENCE ENTRY LIFECYCLE: ┌─────────┐ ┌─────────┐ ┌───────────┐ ┌──────────┐ │ DRAFT │ ───▶ │ STAGED │ ───▶ │ PROMOTED │ ───▶ │ ARCHIVED │ └─────────┘ └─────────┘ └───────────┘ └──────────┘ │ │ │ │ Form submit Auto if POST /promote Manual or POST /evidence gate=READY (manual review) superseded │ │ │ Trigger scores ┌───┴───┐ JSON-LD injected all 5 metrics │ BLOCKED│ on case page └───────┘ Stays draft, user sees 'needs more info' TRANSITION RULES: draft → staged : AUTOMATIC when promo_gate = 'READY' (trigger) draft → draft : If gate = 'BLOCKED', stays draft with feedback staged → promoted : MANUAL via POST /api/evidence/:id/promote staged → draft : If edited and gate becomes 'BLOCKED' promoted → archived: MANUAL or via expiry rule ANY → rescored : Every UPDATE re-triggers scoring | C21: KEY DESIGN DECISIONS: 1. draft → staged is AUTO User doesn't need to know about staging. They fill in the form, and if it's good enough, it advances silently. 2. staged → promoted is MANUAL This is your editorial gate. Even if the scores are perfect, a human decides when it goes live. You can also add a cron Worker to auto-promote staged entries older than N days. 3. Editing can UN-PROMOTE If someone edits a promoted entry and it drops below thresholds, the trigger resets promo_gate to BLOCKED. The status stays 'promoted' but JSON-LD won't render (filtered by promo_gate in the GET endpoint). 4. Scores are NEVER shown to the user They see: • 'Entry saved' (draft) • 'Entry qualified for publication' (staged) • Live on site (promoted) • 'Needs more information' (blocked) They never see 73% completeness or 85 quality.
A23: ── 5. CLOUDFLARE DEPLOYMENT ──
A24: wrangler.toml | B24: name = "openintel-api" main = "src/index.ts" compatibility_date = "2025-01-01" # Hyperdrive binding to your Postgres [[hyperdrive]] binding = "HYPERDRIVE" id = "<your-hyperdrive-config-id>" # Routes [[routes]] pattern = "/api/evidence*" zone_name = "openintel.org" # Optional: D1 for caching / analytics [[d1_databases]] binding = "ANALYTICS" database_name = "openintel-analytics" database_id = "<d1-database-id>" # KV for rate limiting [[kv_namespaces]] binding = "RATE_LIMIT" id = "<kv-namespace-id>" | C24: DEPLOYMENT CONFIG Hyperdrive connects your Cloudflare Worker to Postgres. Setup: 1. npx wrangler hyperdrive create openintel-db \ --connection-string="postgres://user:pass@host:5432/openintel" 2. npx wrangler deploy 3. Point DNS: openintel.org → Cloudflare Optional D1: You could mirror promoted entries to D1 for edge-cached reads. Writes go to Postgres, reads from D1. But Hyperdrive alone is fine for your scale. Rate limiting via KV: Prevent form spam. Track submissions per IP per hour.
A26: ── 6. PROJECT FILE STRUCTURE ──
A27: Directory layout | B27: openintel/ ├── wrangler.toml # Cloudflare config (Section 5) ├── migrations/ │ ├── 001_create_taxonomy.sql # evidence_taxonomy table + seed data │ ├── 002_create_entries.sql # evidence_entries table + indexes │ └── 003_create_scoring_trigger.sql # compute_evidence_scores() trigger ├── src/ │ ├── index.ts # Worker entry point + router │ ├── routes/ │ │ ├── evidence.post.ts # POST /api/evidence (Section 2) │ │ ├── evidence.get.ts # GET /api/evidence (Section 2) │ │ └── evidence.promote.ts # POST /api/evidence/:id/promote │ ├── lib/ │ │ ├── validation.ts # Server-side validation rules │ │ ├── jsonld.ts # buildClaimReviewLD() + buildDatasetLD() │ │ └── taxonomy.ts # DB_TAG enum, tier weights, type map │ └── types.ts # TypeScript interfaces ├── public/ │ ├── evidence-form.html # Form template (Section 3) │ └── form.js # SPA form handler + fetch logic └── package.json | C27: Every section of this spec maps to a file. Migrations run in order on Postgres: psql -d openintel -f migrations/001_create_taxonomy.sql psql -d openintel -f migrations/002_create_entries.sql psql -d openintel -f migrations/003_create_scoring_trigger.sql The lib/taxonomy.ts should be auto-generated from your EVIDENCE_TAXONOMY Excel sheet so the 38 types stay in sync. The jsonld.ts is the same code from your JSONLD_TEMPLATES sheet.

Sheet EVIDENCE_TAXONOMY
A1: OPENINTEL EVIDENCE TAXONOMY | D1: 38 Evidence Types · 6 Tiers · Every claim gets tagged
A2: TYPE # | B2: TIER | C2: EVIDENCE TYPE | D2: DESCRIPTION | E2: EXAMPLES | F2: DB TAG | G2: T-RANGE
B3: T1 — PRIMARY SOURCES (Strongest)
A4: 1 | B4: T1 | C4: Declassified Government Documents | D4: FOIA releases, presidential libraries, national archives. Official records released through declassification processes. | E4: MKUltra, COINTELPRO, Operation Northwoods | F4: declass_gov | G4: T1–T2
A5: 2 | B5: T1 | C5: Congressional/Parliamentary Records | D5: Hearing transcripts, committee reports, testimony under oath. Official legislative investigation records. | E5: Church Committee, Pike Committee, 9/11 Commission | F5: congress_record | G5: T1–T2
A6: 3 | B6: T1 | C6: Court Records | D6: Indictments, trial transcripts, depositions, settlements, judgments. Legally produced under rules of evidence. | E6: Orlikow v. United States, Alex Jones defamation trial | F6: court_record | G6: T1
A7: 4 | B7: T1 | C7: Official Admissions/Apologies | D7: Government or institutional acknowledgments of past programs or wrongdoing. | E7: Tuskegee apology, Lavon Affair admission, CIA torture acknowledgment | F7: official_admit | G7: T1
A8: 5 | B8: T1 | C8: Leaked Documents | D8: Unauthorized disclosures verified by publication in major outlets with editorial oversight. | E8: Wikileaks cables, Snowden docs, Pentagon Papers, Panama Papers | F8: leaked_doc | G8: T1–T2
A9: 6 | B9: T1 | C9: Scientific/Peer-Reviewed Studies | D9: Published research with methodology, replication, and peer review in recognized journals. | E9: NTP fluoride study, VAERS data analysis | F9: peer_reviewed | G9: T1
